Workbook
Name Complej.: #REF!
Name EF: #REF!
Name TAW: #REF!
Name TBF: #REF!
Name TCF: #REF!
Name UUCP: #REF!

Sheet Complejidad
A1: 1. Estime el factor de Ajuste de complejidad del proyecto o producto de acuerdo a las siguientes características
A2: Generales del sistema
B4: Complejidad
B5: Id | C5: Descripción | G5: Prom
B6: 2.1.1 | C6: Comunicación de datos
G7: 1
B8: 2.1.2 | C8: Desempeño
G9: 1
B10: 2.1.3 | C10: Configuración
G11: 1
B12: 2.1.4 | C12: Tasa de Transacciones
G13: 1
B14: 2.1.5 | C14: Captura en línea de datos
G15: 1
B16: 2.1.6 | C16: Eficiencia al usuario Final
G17: 1
B18: 2.1.7 | C18: Actualización en línea
G19: 1
B20: 2.1.8 | C20: Complejidad de Proceso
G21: 1
B22: 2.1.9 | C22: Reusabilidad
G23: 1
B24: Puntos de Complejidad Estimados del proyecto | G24: =SUM(G7:G23) -> 9
B25: Factor de Ajuste de Complejidad del Proyecto | G25: =1 + ((G24-9) / 18) -> 1
C27: Factor de Productividad Estimado | D27: 1 | E27: Puntos Funcionales X Hora
B30: Criterios de Estimación

Sheet E-01
A1: NOTAS:
A3: A) Estime la cantidad estimada minima, promedio y maxima de objetos de Software (Código) que se
A4: desarrollaran para cada requerimiento esta estimación deberá estar basada en la especificación
A5: del requerimiento. La hoja de cálculo automáticamente aplicará el factor de complejidad de cada objeto
A6: B) En caso de ser un requerimiento sencillo con diseño ya conocido estime utilizando únicamnete la columna PROMEDIO
A7: C) Reproduzca esta Hoja por cada requerimiento del proyecto.
A8: D) Solo se deberá escribir en los espacios en blanco de la hoja de cálculo.
A9: E) En caso de tomar consideraciones especiales se deberán documentar en la Sección de Críterios de la hoja de coplejidad
A11: Estimación del Tamaño del Software
A12: Cliente | B12: Bloom Café
A13: Proyecto | B13: Sistema de Gestión de Pedidos
A14: Fecha | B14: 46315
A15: Req. | B15: E-01 Consulta y personalización de productos
A16: Objeto | C16: Puntos Factor de Complejidad | F16: Objetos Estimados | I16: Tamaño Estimado
A17: Id | B17: Nombre | C17: Simple | D17: Medio | E17: Complejo | F17: Simple | G17: Medio | H17: Complejo | I17: Simple | J17: Medio | K17: Complejo | L17: Total
A18: Pantallas
A19: 11101 | B19: Captura | C19: 4 | D19: 10 | E19: 20 | G19: 1 | I19: =C19*F19 -> 0 | J19: =D19*G19 -> 10 | K19: =E19*H19 -> 0 | L19: =I19+J19+K19 -> 10
A20: 11102 | B20: Catálogos (A,B,C) | C20: 2 | D20: 4 | E20: 8 | G20: 1 | I20: =C20*F20 -> 0 | J20: =D20*G20 -> 4 | K20: =E20*H20 -> 0 | L20: =I20+J20+K20 -> 4
A21: 11103 | B21: Configuración | C21: 2 | D21: 4 | E21: 8 | G21: 1 | I21: =C21*F21 -> 0 | J21: =D21*G21 -> 4 | K21: =E21*H21 -> 0 | L21: =I21+J21+K21 -> 4
A22: Reportes
A23: 12101 | B23: Reportes | C23: 4 | D23: 10 | E23: 20 | I23: =C23*F23 -> 0 | J23: =D23*G23 -> 0 | K23: =E23*H23 -> 0 | L23: =I23+J23+K23 -> 0
A24: Procesos
A25: 13101 | B25: Cálculo | C25: 40 | D25: 80 | E25: 120 | G25: 1 | I25: =C25*F25 -> 0 | J25: =D25*G25 -> 80 | K25: =E25*H25 -> 0 | L25: =I25+J25+K25 -> 80
A26: Interfase
A27: 14101 | B27: Importación | C27: 4 | D27: 10 | E27: 40 | I27: =C27*F27 -> 0 | J27: =D27*G27 -> 0 | K27: =E27*H27 -> 0 | L27: =I27+J27+K27 -> 0
A28: 14102 | B28: Exportación | C28: 4 | D28: 10 | E28: 40 | I28: =C28*F28 -> 0 | J28: =D28*G28 -> 0 | K28: =E28*H28 -> 0 | L28: =I28+J28+K28 -> 0
A29: ="Tamaño:"&B15 -> Tamaño:E-01 Consulta y personalización de productos | F29: =SUM(F19:F28) -> 0 | G29: =SUM(G18:G28) -> 4 | H29: =SUM(H19:H28) -> 0 | I29: =SUM(I18:I28) -> 0 | J29: =SUM(J18:J28) -> 98 | K29: =SUM(K18:K28) -> 0 | L29: =SUM(L19:L28) -> 98
A31: Esfuerzo Ajustado Por Factor de Complejidad | F31: (Horas Hombre) | I31: =I29*Complejidad!$G$25 -> 0 | J31: =J29*Complejidad!$G$25 -> 98 | K31: =K29*Complejidad!$G$25 -> 0 | L31: =L29*Complejidad!$G$25 -> 98
A33: Factor Estimado de Productividad(FP) | C33: =Complejidad!D27 -> 1 | F33: (Puntos Funcionales X Hora)
A35: Esfuerzo Estimado Por Factor de Productividad | F35: (Horas Hombre) | I35: =I31/$C$33 -> 0 | J35: =J31/$C$33 -> 98 | K35: =K31/$C$33 -> 0 | L35: =L31/$C$33 -> 98

Sheet E-02
A1: NOTAS:
A3: A) Estime la cantidad estimada minima, promedio y maxima de objetos de Software (Código) que se
A4: desarrollaran para cada requerimiento esta estimación deberá estar basada en la especificación
A5: del requerimiento. La hoja de cálculo automáticamente aplicará el factor de complejidad de cada objeto
A6: B) En caso de ser un requerimiento sencillo con diseño ya conocido estime utilizando únicamnete la columna PROMEDIO
A7: C) Reproduzca esta Hoja por cada requerimiento del proyecto.
A8: D) Solo se deberá escribir en los espacios en blanco de la hoja de cálculo.
A9: E) En caso de tomar consideraciones especiales se deberán documentar en la Sección de Críterios de la hoja de coplejidad
A11: Estimación del Tamaño del Software
A12: Cliente | B12: Bloom Café
A13: Proyecto | B13: Sistema de Gestión de Pedidos
A14: Fecha | B14: 46315
A15: Req. | B15: E-02 Registro y gestión de pedidos
A16: Objeto | C16: Puntos Factor de Complejidad | F16: Objetos Estimados | I16: Tamaño Estimado
A17: Id | B17: Nombre | C17: Simple | D17: Medio | E17: Complejo | F17: Simple | G17: Medio | H17: Complejo | I17: Simple | J17: Medio | K17: Complejo | L17: Total
A18: Pantallas
A19: 11101 | B19: Captura | C19: 4 | D19: 10 | E19: 20 | G19: 2 | I19: =C19*F19 -> 0 | J19: =D19*G19 -> 20 | K19: =E19*H19 -> 0 | L19: =I19+J19+K19 -> 20
A20: 11102 | B20: Catálogos (A,B,C) | C20: 2 | D20: 4 | E20: 8 | G20: 1 | I20: =C20*F20 -> 0 | J20: =D20*G20 -> 4 | K20: =E20*H20 -> 0 | L20: =I20+J20+K20 -> 4
A21: 11103 | B21: Configuración | C21: 2 | D21: 4 | E21: 8 | I21: =C21*F21 -> 0 | J21: =D21*G21 -> 0 | K21: =E21*H21 -> 0 | L21: =I21+J21+K21 -> 0
A22: Reportes
A23: 12101 | B23: Reportes | C23: 4 | D23: 10 | E23: 20 | I23: =C23*F23 -> 0 | J23: =D23*G23 -> 0 | K23: =E23*H23 -> 0 | L23: =I23+J23+K23 -> 0
A24: Procesos
A25: 13101 | B25: Cálculo | C25: 40 | D25: 80 | E25: 120 | G25: 1 | I25: =C25*F25 -> 0 | J25: =D25*G25 -> 80 | K25: =E25*H25 -> 0 | L25: =I25+J25+K25 -> 80
A26: Interfase
A27: 14101 | B27: Importación | C27: 4 | D27: 10 | E27: 40 | I27: =C27*F27 -> 0 | J27: =D27*G27 -> 0 | K27: =E27*H27 -> 0 | L27: =I27+J27+K27 -> 0
A28: 14102 | B28: Exportación | C28: 4 | D28: 10 | E28: 40 | I28: =C28*F28 -> 0 | J28: =D28*G28 -> 0 | K28: =E28*H28 -> 0 | L28: =I28+J28+K28 -> 0
A29: ="Tamaño:"&B15 -> Tamaño:E-02 Registro y gestión de pedidos | F29: =SUM(F19:F28) -> 0 | G29: =SUM(G18:G28) -> 4 | H29: =SUM(H19:H28) -> 0 | I29: =SUM(I18:I28) -> 0 | J29: =SUM(J18:J28) -> 104 | K29: =SUM(K18:K28) -> 0 | L29: =SUM(L19:L28) -> 104
A31: Esfuerzo Ajustado Por Factor de Complejidad | F31: (Horas Hombre) | I31: =I29*Complejidad!$G$25 -> 0 | J31: =J29*Complejidad!$G$25 -> 104 | K31: =K29*Complejidad!$G$25 -> 0 | L31: =L29*Complejidad!$G$25 -> 104
A33: Factor Estimado de Productividad(FP) | C33: =Complejidad!D27 -> 1 | F33: (Puntos Funcionales X Hora)
A35: Esfuerzo Estimado Por Factor de Productividad | F35: (Horas Hombre) | I35: =I31/$C$33 -> 0 | J35: =J31/$C$33 -> 104 | K35: =K31/$C$33 -> 0 | L35: =L31/$C$33 -> 104

Sheet E-03
A1: NOTAS:
A3: A) Estime la cantidad estimada minima, promedio y maxima de objetos de Software (Código) que se
A4: desarrollaran para cada requerimiento esta estimación deberá estar basada en la especificación
A5: del requerimiento. La hoja de cálculo automáticamente aplicará el factor de complejidad de cada objeto
A6: B) En caso de ser un requerimiento sencillo con diseño ya conocido estime utilizando únicamnete la columna PROMEDIO
A7: C) Reproduzca esta Hoja por cada requerimiento del proyecto.
A8: D) Solo se deberá escribir en los espacios en blanco de la hoja de cálculo.
A9: E) En caso de tomar consideraciones especiales se deberán documentar en la Sección de Críterios de la hoja de coplejidad
A11: Estimación del Tamaño del Software
A12: Cliente | B12: Bloom Café
A13: Proyecto | B13: Sistema de Gestión de Pedidos
A14: Fecha | B14: 46315
A15: Req. | B15: E-03 Seguimiento, cancelación y entrega de pedidos
A16: Objeto | C16: Puntos Factor de Complejidad | F16: Objetos Estimados | I16: Tamaño Estimado
A17: Id | B17: Nombre | C17: Simple | D17: Medio | E17: Complejo | F17: Simple | G17: Medio | H17: Complejo | I17: Simple | J17: Medio | K17: Complejo | L17: Total
A18: Pantallas
A19: 11101 | B19: Captura | C19: 4 | D19: 10 | E19: 20 | G19: 2 | I19: =C19*F19 -> 0 | J19: =D19*G19 -> 20 | K19: =E19*H19 -> 0 | L19: =I19+J19+K19 -> 20
A20: 11102 | B20: Catálogos (A,B,C) | C20: 2 | D20: 4 | E20: 8 | G20: 2 | I20: =C20*F20 -> 0 | J20: =D20*G20 -> 8 | K20: =E20*H20 -> 0 | L20: =I20+J20+K20 -> 8
A21: 11103 | B21: Configuración | C21: 2 | D21: 4 | E21: 8 | F21: 1 | I21: =C21*F21 -> 2 | J21: =D21*G21 -> 0 | K21: =E21*H21 -> 0 | L21: =I21+J21+K21 -> 2
A22: Reportes
A23: 12101 | B23: Reportes | C23: 4 | D23: 10 | E23: 20 | G23: 2 | I23: =C23*F23 -> 0 | J23: =D23*G23 -> 20 | K23: =E23*H23 -> 0 | L23: =I23+J23+K23 -> 20
A24: Procesos
A25: 13101 | B25: Cálculo | C25: 40 | D25: 80 | E25: 120 | G25: 1 | I25: =C25*F25 -> 0 | J25: =D25*G25 -> 80 | K25: =E25*H25 -> 0 | L25: =I25+J25+K25 -> 80
A26: Interfase
A27: 14101 | B27: Importación | C27: 4 | D27: 10 | E27: 40 | I27: =C27*F27 -> 0 | J27: =D27*G27 -> 0 | K27: =E27*H27 -> 0 | L27: =I27+J27+K27 -> 0
A28: 14102 | B28: Exportación | C28: 4 | D28: 10 | E28: 40 | I28: =C28*F28 -> 0 | J28: =D28*G28 -> 0 | K28: =E28*H28 -> 0 | L28: =I28+J28+K28 -> 0
A29: ="Tamaño:"&B15 -> Tamaño:E-03 Seguimiento, cancelación y entrega de pedidos | F29: =SUM(F19:F28) -> 1 | G29: =SUM(G18:G28) -> 7 | H29: =SUM(H19:H28) -> 0 | I29: =SUM(I18:I28) -> 2 | J29: =SUM(J18:J28) -> 128 | K29: =SUM(K18:K28) -> 0 | L29: =SUM(L19:L28) -> 130
A31: Esfuerzo Ajustado Por Factor de Complejidad | F31: (Horas Hombre) | I31: =I29*Complejidad!$G$25 -> 2 | J31: =J29*Complejidad!$G$25 -> 128 | K31: =K29*Complejidad!$G$25 -> 0 | L31: =L29*Complejidad!$G$25 -> 130
A33: Factor Estimado de Productividad(FP) | C33: =Complejidad!D27 -> 1 | F33: (Puntos Funcionales X Hora)
A35: Esfuerzo Estimado Por Factor de Productividad | F35: (Horas Hombre) | I35: =I31/$C$33 -> 2 | J35: =J31/$C$33 -> 128 | K35: =K31/$C$33 -> 0 | L35: =L31/$C$33 -> 130

Sheet E-04
A1: NOTAS:
A3: A) Estime la cantidad estimada minima, promedio y maxima de objetos de Software (Código) que se
A4: desarrollaran para cada requerimiento esta estimación deberá estar basada en la especificación
A5: del requerimiento. La hoja de cálculo automáticamente aplicará el factor de complejidad de cada objeto
A6: B) En caso de ser un requerimiento sencillo con diseño ya conocido estime utilizando únicamnete la columna PROMEDIO
A7: C) Reproduzca esta Hoja por cada requerimiento del proyecto.
A8: D) Solo se deberá escribir en los espacios en blanco de la hoja de cálculo.
A9: E) En caso de tomar consideraciones especiales se deberán documentar en la Sección de Críterios de la hoja de coplejidad
A11: Estimación del Tamaño del Software
A12: Cliente | B12: Bloom Café
A13: Proyecto | B13: Sistema de Gestión de Pedidos
A14: Fecha | B14: 46315
A15: Req. | B15: E-04 Administración de productos y promociones
A16: Objeto | C16: Puntos Factor de Complejidad | F16: Objetos Estimados | I16: Tamaño Estimado
A17: Id | B17: Nombre | C17: Simple | D17: Medio | E17: Complejo | F17: Simple | G17: Medio | H17: Complejo | I17: Simple | J17: Medio | K17: Complejo | L17: Total
A18: Pantallas
A19: 11101 | B19: Captura | C19: 4 | D19: 10 | E19: 20 | G19: 2 | I19: =C19*F19 -> 0 | J19: =D19*G19 -> 20 | K19: =E19*H19 -> 0 | L19: =I19+J19+K19 -> 20
A20: 11102 | B20: Catálogos (A,B,C) | C20: 2 | D20: 4 | E20: 8 | G20: 2 | I20: =C20*F20 -> 0 | J20: =D20*G20 -> 8 | K20: =E20*H20 -> 0 | L20: =I20+J20+K20 -> 8
A21: 11103 | B21: Configuración | C21: 2 | D21: 4 | E21: 8 | G21: 1 | I21: =C21*F21 -> 0 | J21: =D21*G21 -> 4 | K21: =E21*H21 -> 0 | L21: =I21+J21+K21 -> 4
A22: Reportes
A23: 12101 | B23: Reportes | C23: 4 | D23: 10 | E23: 20 | F23: 1 | I23: =C23*F23 -> 4 | J23: =D23*G23 -> 0 | K23: =E23*H23 -> 0 | L23: =I23+J23+K23 -> 4
A24: Procesos
A25: 13101 | B25: Cálculo | C25: 40 | D25: 80 | E25: 120 | G25: 1 | I25: =C25*F25 -> 0 | J25: =D25*G25 -> 80 | K25: =E25*H25 -> 0 | L25: =I25+J25+K25 -> 80
A26: Interfase
A27: 14101 | B27: Importación | C27: 4 | D27: 10 | E27: 40 | I27: =C27*F27 -> 0 | J27: =D27*G27 -> 0 | K27: =E27*H27 -> 0 | L27: =I27+J27+K27 -> 0
A28: 14102 | B28: Exportación | C28: 4 | D28: 10 | E28: 40 | I28: =C28*F28 -> 0 | J28: =D28*G28 -> 0 | K28: =E28*H28 -> 0 | L28: =I28+J28+K28 -> 0
A29: ="Tamaño:"&B15 -> Tamaño:E-04 Administración de productos y promociones | F29: =SUM(F19:F28) -> 1 | G29: =SUM(G18:G28) -> 6 | H29: =SUM(H19:H28) -> 0 | I29: =SUM(I18:I28) -> 4 | J29: =SUM(J18:J28) -> 112 | K29: =SUM(K18:K28) -> 0 | L29: =SUM(L19:L28) -> 116
A31: Esfuerzo Ajustado Por Factor de Complejidad | F31: (Horas Hombre) | I31: =I29*Complejidad!$G$25 -> 4 | J31: =J29*Complejidad!$G$25 -> 112 | K31: =K29*Complejidad!$G$25 -> 0 | L31: =L29*Complejidad!$G$25 -> 116
A33: Factor Estimado de Productividad(FP) | C33: =Complejidad!D27 -> 1 | F33: (Puntos Funcionales X Hora)
A35: Esfuerzo Estimado Por Factor de Productividad | F35: (Horas Hombre) | I35: =I31/$C$33 -> 4 | J35: =J31/$C$33 -> 112 | K35: =K31/$C$33 -> 0 | L35: =L31/$C$33 -> 116

Sheet E-05
A1: NOTAS:
A3: A) Estime la cantidad estimada minima, promedio y maxima de objetos de Software (Código) que se
A4: desarrollaran para cada requerimiento esta estimación deberá estar basada en la especificación
A5: del requerimiento. La hoja de cálculo automáticamente aplicará el factor de complejidad de cada objeto
A6: B) En caso de ser un requerimiento sencillo con diseño ya conocido estime utilizando únicamnete la columna PROMEDIO
A7: C) Reproduzca esta Hoja por cada requerimiento del proyecto.
A8: D) Solo se deberá escribir en los espacios en blanco de la hoja de cálculo.
A9: E) En caso de tomar consideraciones especiales se deberán documentar en la Sección de Críterios de la hoja de coplejidad
A11: Estimación del Tamaño del Software
A12: Cliente | B12: Bloom Café
A13: Proyecto | B13: Sistema de Gestión de Pedidos
A14: Fecha | B14: 46315
A15: Req. | B15: E-05 Estadísticas de pedidos y ventas
A16: Objeto | C16: Puntos Factor de Complejidad | F16: Objetos Estimados | I16: Tamaño Estimado
A17: Id | B17: Nombre | C17: Simple | D17: Medio | E17: Complejo | F17: Simple | G17: Medio | H17: Complejo | I17: Simple | J17: Medio | K17: Complejo | L17: Total
A18: Pantallas
A19: 11101 | B19: Captura | C19: 4 | D19: 10 | E19: 20 | F19: 1 | I19: =C19*F19 -> 4 | J19: =D19*G19 -> 0 | K19: =E19*H19 -> 0 | L19: =I19+J19+K19 -> 4
A20: 11102 | B20: Catálogos (A,B,C) | C20: 2 | D20: 4 | E20: 8 | I20: =C20*F20 -> 0 | J20: =D20*G20 -> 0 | K20: =E20*H20 -> 0 | L20: =I20+J20+K20 -> 0
A21: 11103 | B21: Configuración | C21: 2 | D21: 4 | E21: 8 | I21: =C21*F21 -> 0 | J21: =D21*G21 -> 0 | K21: =E21*H21 -> 0 | L21: =I21+J21+K21 -> 0
A22: Reportes
A23: 12101 | B23: Reportes | C23: 4 | D23: 10 | E23: 20 | G23: 1 | I23: =C23*F23 -> 0 | J23: =D23*G23 -> 10 | K23: =E23*H23 -> 0 | L23: =I23+J23+K23 -> 10
A24: Procesos
A25: 13101 | B25: Cálculo | C25: 40 | D25: 80 | E25: 120 | G25: 1 | I25: =C25*F25 -> 0 | J25: =D25*G25 -> 80 | K25: =E25*H25 -> 0 | L25: =I25+J25+K25 -> 80
A26: Interfase
A27: 14101 | B27: Importación | C27: 4 | D27: 10 | E27: 40 | I27: =C27*F27 -> 0 | J27: =D27*G27 -> 0 | K27: =E27*H27 -> 0 | L27: =I27+J27+K27 -> 0
A28: 14102 | B28: Exportación | C28: 4 | D28: 10 | E28: 40 | I28: =C28*F28 -> 0 | J28: =D28*G28 -> 0 | K28: =E28*H28 -> 0 | L28: =I28+J28+K28 -> 0
A29: ="Tamaño:"&B15 -> Tamaño:E-05 Estadísticas de pedidos y ventas | F29: =SUM(F19:F28) -> 1 | G29: =SUM(G18:G28) -> 2 | H29: =SUM(H19:H28) -> 0 | I29: =SUM(I18:I28) -> 4 | J29: =SUM(J18:J28) -> 90 | K29: =SUM(K18:K28) -> 0 | L29: =SUM(L19:L28) -> 94
A31: Esfuerzo Ajustado Por Factor de Complejidad | F31: (Horas Hombre) | I31: =I29*Complejidad!$G$25 -> 4 | J31: =J29*Complejidad!$G$25 -> 90 | K31: =K29*Complejidad!$G$25 -> 0 | L31: =L29*Complejidad!$G$25 -> 94
A33: Factor Estimado de Productividad(FP) | C33: =Complejidad!D27 -> 1 | F33: (Puntos Funcionales X Hora)
A35: Esfuerzo Estimado Por Factor de Productividad | F35: (Horas Hombre) | I35: =I31/$C$33 -> 4 | J35: =J31/$C$33 -> 90 | K35: =K31/$C$33 -> 0 | L35: =L31/$C$33 -> 94

Sheet E-06
A1: NOTAS:
A3: A) Estime la cantidad estimada minima, promedio y maxima de objetos de Software (Código) que se
A4: desarrollaran para cada requerimiento esta estimación deberá estar basada en la especificación
A5: del requerimiento. La hoja de cálculo automáticamente aplicará el factor de complejidad de cada objeto
A6: B) En caso de ser un requerimiento sencillo con diseño ya conocido estime utilizando únicamnete la columna PROMEDIO
A7: C) Reproduzca esta Hoja por cada requerimiento del proyecto.
A8: D) Solo se deberá escribir en los espacios en blanco de la hoja de cálculo.
A9: E) En caso de tomar consideraciones especiales se deberán documentar en la Sección de Críterios de la hoja de coplejidad
A11: Estimación del Tamaño del Software
A12: Cliente | B12: Bloom Café
A13: Proyecto | B13: Sistema de Gestión de Pedidos
A14: Fecha | B14: 46315
A15: Req. | B15: E-06 Administración de acceso y permisos
A16: Objeto | C16: Puntos Factor de Complejidad | F16: Objetos Estimados | I16: Tamaño Estimado
A17: Id | B17: Nombre | C17: Simple | D17: Medio | E17: Complejo | F17: Simple | G17: Medio | H17: Complejo | I17: Simple | J17: Medio | K17: Complejo | L17: Total
A18: Pantallas
A19: 11101 | B19: Captura | C19: 4 | D19: 10 | E19: 20 | G19: 2 | I19: =C19*F19 -> 0 | J19: =D19*G19 -> 20 | K19: =E19*H19 -> 0 | L19: =I19+J19+K19 -> 20
A20: 11102 | B20: Catálogos (A,B,C) | C20: 2 | D20: 4 | E20: 8 | G20: 1 | I20: =C20*F20 -> 0 | J20: =D20*G20 -> 4 | K20: =E20*H20 -> 0 | L20: =I20+J20+K20 -> 4
A21: 11103 | B21: Configuración | C21: 2 | D21: 4 | E21: 8 | H21: 2 | I21: =C21*F21 -> 0 | J21: =D21*G21 -> 0 | K21: =E21*H21 -> 16 | L21: =I21+J21+K21 -> 16
A22: Reportes
A23: 12101 | B23: Reportes | C23: 4 | D23: 10 | E23: 20 | I23: =C23*F23 -> 0 | J23: =D23*G23 -> 0 | K23: =E23*H23 -> 0 | L23: =I23+J23+K23 -> 0
A24: Procesos
A25: 13101 | B25: Cálculo | C25: 40 | D25: 80 | E25: 120 | G25: 1 | I25: =C25*F25 -> 0 | J25: =D25*G25 -> 80 | K25: =E25*H25 -> 0 | L25: =I25+J25+K25 -> 80
A26: Interfase
A27: 14101 | B27: Importación | C27: 4 | D27: 10 | E27: 40 | I27: =C27*F27 -> 0 | J27: =D27*G27 -> 0 | K27: =E27*H27 -> 0 | L27: =I27+J27+K27 -> 0
A28: 14102 | B28: Exportación | C28: 4 | D28: 10 | E28: 40 | I28: =C28*F28 -> 0 | J28: =D28*G28 -> 0 | K28: =E28*H28 -> 0 | L28: =I28+J28+K28 -> 0
A29: ="Tamaño:"&B15 -> Tamaño:E-06 Administración de acceso y permisos | F29: =SUM(F19:F28) -> 0 | G29: =SUM(G18:G28) -> 4 | H29: =SUM(H19:H28) -> 2 | I29: =SUM(I18:I28) -> 0 | J29: =SUM(J18:J28) -> 104 | K29: =SUM(K18:K28) -> 16 | L29: =SUM(L19:L28) -> 120
A31: Esfuerzo Ajustado Por Factor de Complejidad | F31: (Horas Hombre) | I31: =I29*Complejidad!$G$25 -> 0 | J31: =J29*Complejidad!$G$25 -> 104 | K31: =K29*Complejidad!$G$25 -> 16 | L31: =L29*Complejidad!$G$25 -> 120
A33: Factor Estimado de Productividad(FP) | C33: =Complejidad!D27 -> 1 | F33: (Puntos Funcionales X Hora)
A35: Esfuerzo Estimado Por Factor de Productividad | F35: (Horas Hombre) | I35: =I31/$C$33 -> 0 | J35: =J31/$C$33 -> 104 | K35: =K31/$C$33 -> 16 | L35: =L31/$C$33 -> 120

Sheet Puntos de Función
B5: Estimación de Esfuerzo de Reqerimientos
B7: No. | C7: Requerimientos | D7: Esfuerzo
B8: 1 | C8: E-01 Consulta y personalización de productos | D8: ='E-01'!L35 -> 98
B9: =B8+1 -> 2 | C9: E-02 Registro y gestión de pedidos | D9: ='E-02'!L35 -> 104
B10: =B9+1 -> 3 | C10: E-03 Seguimiento, cancelación y entrega de pedidos | D10: ='E-03'!L35 -> 130
B11: =B10+1 -> 4 | C11: E-04 Administración de productos y promociones | D11: ='E-04'!L35 -> 116
B12: =B11+1 -> 5 | C12: E-05 Estadísticas de pedidos y ventas | D12: ='E-05'!L35 -> 94
B13: =B12+1 -> 6 | C13: E-06 Administración de acceso y permisos | D13: ='E-06'!L35 -> 120
B14: Total de Requerimientos | D14: =SUM(D8:D13) -> 662

Sheet Estimación de Esfuerzo y Tamaño
B5: Estimación de Esfuerzo
B7: ESTIMACION DE ESFUERZO
E8: =SUM(E10:E16) -> 2 | F8: =SUM(F10:F16) -> 1324
B9: Nº | C9: Etapa | D9: EI | E9: % | F9: EC
B10: 1 | C10: Planificación | E10: 0.1 | F10: =D12*E10 -> 66.2
B11: 2 | C11: Análisis y Diseño | E11: 0.3 | F11: =D12*E11 -> 198.6
B12: =B11+1 -> 3 | C12: Desarrollo | D12: ='Puntos de Función'!D14 -> 662 | E12: 1 | F12: =D12*E12 -> 662
B13: =B12+1 -> 4 | C13: Prueba | E13: 0.25 | F13: =D12*E13 -> 165.5
B14: =B13+1 -> 5 | C14: Despliegue | E14: 0.1 | F14: =D12*E14 -> 66.2
B15: =B14+1 -> 6 | C15: Administración de la Configuración | E15: 0.1 | F15: =D12*E15 -> 66.2
B16: =B15+1 -> 7 | C16: Seguimiento y Supervisión | E16: 0.15 | F16: =D12*E16 -> 99.3
B17: =B16+1 -> 8 | C17: Horas de Investigación | E17: 0.05 | F17: =D12*E17 -> 33.1

Sheet Riesgos
B5: Formato de Estimaciones | I5: Formato de Estimaciones
B7: Cliente: <CLIENTE>
B8: Proyecto: <PROYECTO>
A10: RIESGOS | I10: ESTRATEGIAS DE MITIGACIÓN
G11: =SUM(G13:G32) -> 0
A12: Nº | B12: Nombre | C12: PR | D12: IMP | E12: E | F12: COMP | G12: HS | I12: ESTRATEGIAS
A13: 1 | E13: =IF((C13*D13)=0,"",C13*D13) | F13: ='Estimación de Esfuerzo y Tamaño'!F12 -> 662 | G13: =IF(C13=0,,IF((E13*F13*IF(I13=0,2,1))=0,"",ROUND(E13*F13*IF(I13=0,2,1),0))) -> 0 | I13: Algo
A14: =A13+1 -> 2 | E14: =IF((C14*D14)=0,"",C14*D14) | F14: =$F$13 -> 662 | G14: =IF(C14=0,,IF((E14*F14*IF(I14=0,2,1))=0,"",ROUND(E14*F14*IF(I14=0,2,1),0))) -> 0
A15: =A14+1 -> 3 | E15: =IF((C15*D15)=0,"",C15*D15) | F15: =$F$13 -> 662 | G15: =IF(C15=0,,IF((E15*F15*IF(I15=0,2,1))=0,"",ROUND(E15*F15*IF(I15=0,2,1),0))) -> 0
A16: =A15+1 -> 4 | E16: =IF((C16*D16)=0,"",C16*D16) | F16: =$F$13 -> 662 | G16: =IF(C16=0,,IF((E16*F16*IF(I16=0,2,1))=0,"",ROUND(E16*F16*IF(I16=0,2,1),0))) -> 0
A17: =A16+1 -> 5 | E17: =IF((C17*D17)=0,"",C17*D17) | F17: =$F$13 -> 662 | G17: =IF(C17=0,,IF((E17*F17*IF(I17=0,2,1))=0,"",ROUND(E17*F17*IF(I17=0,2,1),0))) -> 0
A18: =A17+1 -> 6 | E18: =IF((C18*D18)=0,"",C18*D18) | F18: =$F$13 -> 662 | G18: =IF(C18=0,,IF((E18*F18*IF(I18=0,2,1))=0,"",ROUND(E18*F18*IF(I18=0,2,1),0))) -> 0
A19: =A18+1 -> 7 | E19: =IF((C19*D19)=0,"",C19*D19) | F19: =$F$13 -> 662 | G19: =IF(C19=0,,IF((E19*F19*IF(I19=0,2,1))=0,"",ROUND(E19*F19*IF(I19=0,2,1),0))) -> 0
A20: =A19+1 -> 8 | E20: =IF((C20*D20)=0,"",C20*D20) | F20: =$F$13 -> 662 | G20: =IF(C20=0,,IF((E20*F20*IF(I20=0,2,1))=0,"",ROUND(E20*F20*IF(I20=0,2,1),0))) -> 0
A21: =A20+1 -> 9 | E21: =IF((C21*D21)=0,"",C21*D21) | F21: =$F$13 -> 662 | G21: =IF(C21=0,,IF((E21*F21*IF(I21=0,2,1))=0,"",ROUND(E21*F21*IF(I21=0,2,1),0))) -> 0
A22: =A21+1 -> 10 | E22: =IF((C22*D22)=0,"",C22*D22) | F22: =$F$13 -> 662 | G22: =IF(C22=0,,IF((E22*F22*IF(I22=0,2,1))=0,"",ROUND(E22*F22*IF(I22=0,2,1),0))) -> 0
A23: =A22+1 -> 11 | E23: =IF((C23*D23)=0,"",C23*D23) | F23: =$F$13 -> 662 | G23: =IF(C23=0,,IF((E23*F23*IF(I23=0,2,1))=0,"",ROUND(E23*F23*IF(I23=0,2,1),0))) -> 0
A24: =A23+1 -> 12 | E24: =IF((C24*D24)=0,"",C24*D24) | F24: =$F$13 -> 662 | G24: =IF(C24=0,,IF((E24*F24*IF(I24=0,2,1))=0,"",ROUND(E24*F24*IF(I24=0,2,1),0))) -> 0
A25: =A24+1 -> 13 | E25: =IF((C25*D25)=0,"",C25*D25) | F25: =$F$13 -> 662 | G25: =IF(C25=0,,IF((E25*F25*IF(I25=0,2,1))=0,"",ROUND(E25*F25*IF(I25=0,2,1),0))) -> 0
... A32: =A31+1 -> 20 | E32: =IF((C32*D32)=0,"",C32*D32) | F32: =$F$13 -> 662 | G32: =IF(C32=0,,IF((E32*F32*IF(I32=0,2,1))=0,"",ROUND(E32*F32*IF(I32=0,2,1),0))) -> 0

Sheet Planilla de Precios
B5: Planilla de Precios
B7: PLANILLA DE PRECIOS
D8: HRS | E8: COSTO | G8: VENTA MERCADO
C9: TOTAL | D9: =SUM(D11,D21,D44) -> 1357.1 | E9: =SUM(E11,E21,E44) -> 621038.75 | G9: =SUM(G11,G21,G44) -> 610695
C11: ETAPAS | D11: =SUM(D13:D20) -> 1357.1 | E11: =SUM(F13:F20) -> 621038.75 | G11: =SUM(H13:H20) -> 610695
B12: Nº | C12: Nombre | D12: HRS | E12: $/HR | F12: TOTAL | G12: $/HR | H12: TOTAL
B13: 1 | C13: ='Estimación de Esfuerzo y Tamaño'!C10 -> Planificación | D13: ='Estimación de Esfuerzo y Tamaño'!F10 -> 66.2 | E13: 375 | F13: =D13*E13 -> 24825 | G13: 450 | H13: =D13*G13 -> 29790
B14: =B13+1 -> 2 | C14: ='Estimación de Esfuerzo y Tamaño'!C11 -> Análisis y Diseño | D14: ='Estimación de Esfuerzo y Tamaño'!F11 -> 198.6 | E14: 250 | F14: =D14*E14 -> 49650 | G14: 450 | H14: =D14*G14 -> 89370
B15: =B14+1 -> 3 | C15: ='Estimación de Esfuerzo y Tamaño'!C12 -> Desarrollo | D15: ='Estimación de Esfuerzo y Tamaño'!F12 -> 662 | E15: 625 | F15: =D15*E15 -> 413750 | G15: 450 | H15: =D15*G15 -> 297900
B16: =B15+1 -> 4 | C16: ='Estimación de Esfuerzo y Tamaño'!C13 -> Prueba | D16: ='Estimación de Esfuerzo y Tamaño'!F13 -> 165.5 | E16: 312.5 | F16: =D16*E16 -> 51718.75 | G16: 450 | H16: =D16*G16 -> 74475
B17: =B16+1 -> 5 | C17: ='Estimación de Esfuerzo y Tamaño'!C14 -> Despliegue | D17: ='Estimación de Esfuerzo y Tamaño'!F14 -> 66.2 | E17: 100 | F17: =D17*E17 -> 6620 | G17: 450 | H17: =D17*G17 -> 29790
B18: =B17+1 -> 6 | C18: ='Estimación de Esfuerzo y Tamaño'!C15 -> Administración de la Configuración | D18: ='Estimación de Esfuerzo y Tamaño'!F15 -> 66.2 | E18: 250 | F18: =D18*E18 -> 16550 | G18: 450 | H18: =D18*G18 -> 29790
B19: =B18+1 -> 7 | C19: ='Estimación de Esfuerzo y Tamaño'!C16 -> Seguimiento y Supervisión | D19: ='Estimación de Esfuerzo y Tamaño'!F16 -> 99.3 | E19: 375 | F19: =D19*E19 -> 37237.5 | G19: 450 | H19: =D19*G19 -> 44685
B20: =B19+1 -> 8 | C20: ='Estimación de Esfuerzo y Tamaño'!C17 -> Horas de Investigación | D20: ='Estimación de Esfuerzo y Tamaño'!F17 -> 33.1 | E20: 625 | F20: =D20*E20 -> 20687.5 | G20: 450 | H20: =D20*G20 -> 14895
C21: ADICIONALES | D21: =SUM(D23:D43) -> 0 | E21: =SUM(F23:F43) -> 0 | G21: =SUM(H23:H43) -> 0
B22: Nº | C22: Nombre | D22: HRS | E22: $/HS | F22: TOTAL | G22: $/HS | H22: TOTAL
B23: 1 | C23: [Capacitación interna] | E23: 15 | F23: =D23*E23 -> 0 | G23: 450 | H23: =D23*G23 -> 0
B24: 2 | C24: [Transferencia Tecnológica] | E24: 0 | F24: =D24*E24 -> 0 | G24: 0 | H24: =D24*G24 -> 0
B25: 3 | C25: [Relevamiento de Infraestructura] | E25: 0 | F25: =D25*E25 -> 0 | G25: 0 | H25: =D25*G25 -> 0
B26: 4 | C26: [Diseño Gráfico] | E26: 0 | F26: =D26*E26 -> 0 | G26: 0 | H26: =D26*G26 -> 0
B27: 5 | C27: [Viáticos] | E27: 0 | F27: =D27*E27 -> 0 | G27: 0 | H27: =D27*G27 -> 0
B28: 6 | C28: [Garantía] | E28: 0 | F28: =D28*E28 -> 0 | G28: 0 | H28: =D28*G28 -> 0
B29: 7 | E29: 0 | F29: =D29*E29 -> 0 | G29: 0 | H29: =D29*G29 -> 0
B30: 8 | E30: 0 | F30: =D30*E30 -> 0 | G30: 0 | H30: =D30*G30 -> 0
B31: 9 | E31: 0 | F31: =D31*E31 -> 0 | G31: 0 | H31: =D31*G31 -> 0
B32: 10 | E32: 0 | F32: =D32*E32 -> 0 | G32: 0 | H32: =D32*G32 -> 0
B33: 11 | E33: 0 | F33: =D33*E33 -> 0 | G33: 0 | H33: =D33*G33 -> 0
B34: 12 | E34: 0 | F34: =D34*E34 -> 0 | G34: 0 | H34: =D34*G34 -> 0
B35: 13 | E35: 0 | F35: =D35*E35 -> 0 | G35: 0 | H35: =D35*G35 -> 0
B36: 14 | E36: 0 | F36: =D36*E36 -> 0 | G36: 0 | H36: =D36*G36 -> 0
B37: 15 | E37: 0 | F37: =D37*E37 -> 0 | G37: 0 | H37: =D37*G37 -> 0
B38: 16 | E38: 0 | F38: =D38*E38 -> 0 | G38: 0 | H38: =D38*G38 -> 0
B39: 17 | E39: 0 | F39: =D39*E39 -> 0 | G39: 0 | H39: =D39*G39 -> 0
B40: 18 | E40: 0 | F40: =D40*E40 -> 0 | G40: 0 | H40: =D40*G40 -> 0
... B43: 21 | E43: 0 | F43: =D43*E43 -> 0 | G43: 0 | H43: =D43*G43 -> 0
C44: RIESGOS | D44: =SUM(D46:D65) -> 0 | E44: =SUM(F46:F65) -> 0 | G44: =SUM(H46:H65) -> 0
B45: No | C45: Nombre | D45: HRS | E45: $/HS | F45: TOTAL | G45: $/HS | H45: TOTAL
B46: 1 | C46: =Riesgos!B13 -> 0 | D46: =Riesgos!G13 -> 0 | E46: 94 | F46: =D46*E46 -> 0 | G46: 94 | H46: =D46*G46 -> 0
B47: =B46+1 -> 2 | C47: =Riesgos!B14 -> 0 | D47: =Riesgos!G14 -> 0 | F47: =D47*E47 -> 0 | H47: =D47*G47 -> 0
B48: =B47+1 -> 3 | C48: =Riesgos!B15 -> 0 | D48: =Riesgos!G15 -> 0 | F48: =D48*E48 -> 0 | H48: =D48*G48 -> 0
...

Sheet Historia de Proy
C2: %
B3: Proyecto | C3: Planificación | D3: Análisis y Diseño | E3: Desarrollo | F3: Prueba | G3: Despliegue | H3: Administración de la Configuración | I3: Seguimiento y Supervisión | J3: Horas de Investigación

Sheet Criterios de Complejidad
A1: CRITERIOS DE COMPLEJIDAD
A2: 2.1 | B2: Comunicación de Datos
B3: Proceso sin despliegue ni impresión. | C3: 1
B4: Proceso con desplegados y/o impresión. | C4: 2
A5: 2.2 | B5: Desempeño
B6: Sin requerimiento específico de desempeño. | C6: 1
B7: Cuidar tiempo de respuesta en horas de negocio pico. | C7: 2
B8: Requiere análisis de desempeño. | C8: 3
A9: 2.3 | B9: Configuración
B10: Restricciones operacionales sin esfuerzo especial. | C10: 1
B11: Consideraciones de seguridad y/o sincronía con otros componentes. | C11: 2
B12: Consideración especial de diseño para sincronía con otros componentes. | C12: 3
A13: 2.4 | B13: Tasa de Transacciones
B14: Sin periodos pico de transacciones. | C14: 1
B15: Con periodos pico de transacciones diarios o semanales. | C15: 2
B16: Alto nivel de transacciones constante. | C16: 3
A17: 2.5 | B17: Captura de Datos en Línea
B18: Proceso de transacciones en forma batch. | C18: 1
B19: Hasta 30% deTransacciones interactivas con captura de datos. | C19: 2
B20: Más de 30% deTransacciones interactivas con captura de datos. | C20: 3
A21: 2.6 | B21: Eficiencia al usuario final
B22: Poca funcionalidad en línea para el usuario final. | C22: 1
B23: Requiere funcionalidad en línea para el usuario final. | C23: 2
B24: Requerimientos de diseño especial de tareas para factores humanos. | C24: 3
A25: 2.7 | B25: Actualización en Línea
B26: Volúmen de actualización bajo y facilmente recuperable. | C26: 1
B27: Volúmen de actualización medio protegiendo pérdida de datos. | C27: 2
B28: Requiere procedimientos de recuperación automáticos. | C28: 3
A29: 2.8 | B29: Complejidad de Proceso.
B30: Proceso de registro (auditoria), | C30: 1
B31: Proceso lógico y/o matemático. | C31: 2
B32: Proceso complejo, requiere multiples posibilidades de I/O. | C32: 3
A33: 2.9 | B33: Reusabilidad
B34: Código reusable dentro de la misma aplicación. | C34: 1
B35: Código reusable en otras aplicaciones con poco mantenimiento. | C35: 2
B36: Código empacado para reuso con mantenimiento parametrizado. | C36: 3

Sheet Historial de cambios
B1: Hisorial del Proyecto
B2: Revisión | C2: Resumen del cambio | D2: Responsable del cambio | E2: Aprobó | F2: Fecha
B19: Historial del Formato
B20: Revisión | C20: Resumen del cambio | D20: Responsable del cambio | E20: Aprobó | F20: Fecha
B21: PA1 | C21: Primer Propuesta | D21: Mauricio Ramos | F21: 46315
